Workbook

Sheet How to use
A1: Voxistics scope (MoSCoW)
A3: Horizon (edit this): the next playable build -- a world you can build in, decorate and hear, with item logistics decided.
A5: Must -- the horizon fails without it.
A6: Should -- important, but the horizon still works without it.
A7: Could -- nice to have if it's cheap; first to drop.
A8: Won't -- not this horizon (parked, not rejected). The dev pile lives here.
A10: How we use it
A11: 1. Before new work starts, it needs a row here. New ideas enter as Could or Won't unless the owner says otherwise.
A12: 2. Only the owner sets Must. Claude's suggestions say 'Claude (proposed)' in Decided by until the owner decides.
A13: 3. Priority and Status are drop-downs; Summary counts update by themselves.
A14: 4. Add a row at the bottom of Scope with the next ID (S040, S041, ...). Example: S040 | Audio | Footstep volume option | Could | Not started | Only if footfalls stay | 10.4 | Owner
A15: 5. When a horizon ships, move its Won'ts up for review and set a new horizon above.

Sheet Scope
A1: ID | B1: Area | C1: Item | D1: Priority | E1: Status | F1: Notes / boundary | G1: Design ref | H1: Decided by
A2: S001 | B2: Engine | C2: Chunked world, streaming, eviction, regeneration | D2: Must | E2: Done | G2: Part II | H2: Owner
A3: S002 | B3: Engine | C3: Save/load: slots, autosave, backups, settings file | D3: Must | E3: Done | G3: Part VII | H3: Owner
A4: S003 | B4: Engine | C4: Native tests + frame profiler (F3) | D4: Must | E4: Done | F4: Every change keeps tests at zero failures | G4: Parts XVI-XVII | H4: Owner
A5: S004 | B5: Engine | C5: Lagless rule: cost scales with what's on screen or changing | D5: Must | E5: In progress | F5: Standing rule, never 'done' | G5: CLAUDE.md | H5: Owner
A6: S005 | B6: Engine | C6: Release-build performance check on the owner's PC | D6: Should | E6: Not started | F6: The Ctrl+F3 report tool exists (perf_report.txt); running the check awaits the owner | G6: Part XVI | H6: Claude (proposed)
A7: S006 | B7: Blocks & art | C7: Block registry, shapes, 32 px materials with normal/shine/glow maps | D7: Must | E7: Done | F7: 32 px chosen by owner | G7: 4.3, 4.13 | H7: Owner
A8: S007 | B8: Blocks & art | C8: Natural, dark, genesis and custodian material sets | D8: Must | E8: Done | G8: 4.3 | H8: Owner
A9: S008 | B9: Blocks & art | C9: Plant cards | D9: Must | E9: Done | G9: 4.14 | H9: Owner
A10: S009 | B10: Blocks & art | C10: Faceted props + dwelling/industry pieces (40 blocks) | D10: Must | E10: Done | F10: In the library only, not world gen yet | G10: 4.15 | H10: Owner
A11: S010 | B11: Blocks & art | C11: Try the library out in the landscape | D11: Must | E11: In progress | F11: Owner play-test; decides names and what stays | G11: 4.15 | H11: Owner
A12: S011 | B12: Blocks & art | C12: Name pass over all blocks | D12: Should | E12: Not started | F12: After the landscape try-out | G12: Part VIII | H12: Owner
A13: S012 | B13: Blocks & art | C13: Landmark shapes: canopy cap, coil stalk | D13: Could | E13: Done | F13: Glowcap, moss canopy, fern coil, sprout coil in the library | G13: 4.15 | H13: Owner
A14: S013 | B14: Blocks & art | C14: Parked decorative set: stained glass, porcelain floral, rune shrine | D14: Won't | E14: Parked | F14: Dev pile; not this horizon | G14: Part XX | H14: Owner
A15: S014 | B15: World | C15: World / biome generation using the library blocks and props | D15: Should | E15: Not started | F15: 'Coming in the pipeline'; not started | G15: Part II | H15: Owner
A16: S015 | B16: Rendering | C16: Lighting, shadows, atmosphere, clouds, bloom, see-through blocks, glow light | D16: Must | E16: Done | G16: 4.8-4.12 | H16: Owner
A17: S016 | B17: Rendering | C17: Soft filtering / colour bleed / large-scale variation comparison | D17: Could | E17: Done | F17: Owner picked D; colour bleed dropped after the playtest (halo). Variation + distance filtering kept (4.16) | G17: Part XX | H17: Owner
A18: S017 | B18: Gameplay | C18: Movement: sprint, crouch, power slide | D18: Must | E18: Done | G18: 4.7 | H18: Owner
A19: S018 | B19: Gameplay | C19: Block library + 10-slot hotbar | D19: Must | E19: Done | G19: 4.3 | H19: Owner
A20: S019 | B20: Gameplay | C20: Debug time control (F8, [ ]) | D20: Must | E20: Done | G20: Part XV | H20: Owner
A21: S020 | B21: Industry | C21: Item logistics: pulse through pipes | D21: Must | E21: In progress | F21: Built: harvester at a constant rate (faster under The Line); plain/clockwise/anticlockwise pipes give pulse spin; networks share out to stores (unlimited) and the machine; open ends fire straight, facing mouths catch; store view with bead heaps. Open: what harvesters draw from, what pulse becomes. | G21: Part VI | H21: Owner
A22: S021 | B22: Industry | C22: First working machine (the placeholder becomes real) | D22: Should | E22: Not started | F22: Core of the factory game. Logistics decided (pulse); waits on what pulse becomes / how it is burned | G22: Part VI | H22: Claude (proposed)
A23: S022 | B23: Industry | C23: Byproducts and land health (industry safe when well run) | D23: Won't | E23: Parked | F23: Dev pile; core direction but not this horizon | G23: Part XX | H23: Owner
A24: S023 | B24: Industry | C24: Essence as a transmutation economy | D24: Could | E24: Not started | F24: Candidate direction only | G24: Part XIX | H24: Claude (proposed)
A25: S024 | B25: Threat | C25: Ooze rifts born of neglect | D25: Won't | E25: Parked | F25: Dev pile | G25: Part XX | H25: Owner
A26: S025 | B26: Simulation | C26: Fluids | D26: Won't | E26: Parked | F26: Dev pile; heavy | G26: Part XX | H26: Owner
A27: S026 | B27: Simulation | C27: Vapours and gases | D27: Won't | E27: Parked | F27: Dev pile; heavy | G27: Part XX | H27: Owner
A28: S027 | B28: Simulation | C28: Plants drop when their support is removed | D28: Won't | E28: Parked | F28: Dev pile | G28: Part XX | H28: Owner
A29: S028 | B29: Audio | C29: Day-cycle music (one clock) | D29: Must | E29: Done | G29: Part XIV | H29: Owner
A30: S029 | B30: Audio | C30: World sound palette + three soundscape axes | D30: Must | E30: Done | F30: Owner finds it plain; develop later | G30: 10.4 | H30: Owner
A31: S030 | B31: Audio | C31: Develop the palette's character further | D31: Could | E31: Not started | F31: When the game's direction is clearer | G31: 10.4 | H31: Owner
A32: S031 | B32: Audio | C32: Machine sounds react to the placeholder machine | D32: Must | E32: Done | F32: Online on placing; hum and rhythm near machines | G32: 10.4 | H32: Owner
A33: S032 | B33: Audio | C33: Positional (stereo) sound | D33: Could | E33: Done | F33: Owner: go ahead. Placed sounds pan, ping-pong echo, Mono audio toggle | G33: 10.3 | H33: Owner
A34: S033 | B34: Audio | C34: Sounds waiting on systems: mending, rift closed, rift omens | D34: Won't | E34: Parked | F34: Built and tested; nothing triggers them yet | G34: 10.4 | H34: Claude (proposed)
A35: S034 | B35: The Line | C35: The Line prototype: travelling pivot, clockwise spin, time expression | D35: Must | E35: Done | F35: Playtest fixes: pivot now lands on the spot you actually spend time in x and z (16-block cells remembering where their time was spent; 30-min half-life). Expression (owner's pick): the visible sky races ahead near the line and runs slow after you leave; sun and light keep the real clock; wobble kept faint. | G35: Part XVIII | H35: Owner
A36: S035 | B36: The Line | C36: Hide the debug marker once the sky effect is signed off | D36: Should | E36: Not started | G36: Part XVIII | H36: Claude (proposed)
A37: S036 | B37: The Line | C37: Player structures as extra pivot sources | D37: Could | E37: Not started | F37: Owner expected the essence attractor to do this; today it doesn't (it only draws from convergence zones). Owner to decide whether attractors should pull The Line's pivot. | G37: Part XVIII | H37: Claude (proposed)
A38: S038 | B38: Standing rules | C38: Nothing anyone owns: no brands, currencies, crypto, borrowed art or names | D38: Must | E38: In progress | F38: Standing rule | G38: Part VIII | H38: Owner
A39: S039 | B39: Standing rules | C39: Photosensitivity: nothing flashes more than 3 times a second | D39: Must | E39: In progress | F39: Standing rule | G39: Part XI | H39: Owner
A40: S040 | B40: Audio | C40: Vocal ad-libs and footfalls | D40: Must | E40: Done | F40: Owner: keep | G40: 10.4 | H40: Owner
...

Sheet Summary
A1: Scope at a glance
A2: Counts update from the Scope sheet.
A4: Priority | B4: Done | C4: In progress | D4: Not started | E4: Parked | F4: Total | G4: Done %
A5: Must | B5: =COUNTIFS(Scope!$D$2:$D$300,$A5,Scope!$E$2:$E$300,B$4) | C5: =COUNTIFS(Scope!$D$2:$D$300,$A5,Scope!$E$2:$E$300,C$4) | D5: =COUNTIFS(Scope!$D$2:$D$300,$A5,Scope!$E$2:$E$300,D$4) | E5: =COUNTIFS(Scope!$D$2:$D$300,$A5,Scope!$E$2:$E$300,E$4) | F5: =SUM(B5:E5) | G5: =IF(F5=0,0,B5/F5)
A6: Should | B6: =COUNTIFS(Scope!$D$2:$D$300,$A6,Scope!$E$2:$E$300,B$4) | C6: =COUNTIFS(Scope!$D$2:$D$300,$A6,Scope!$E$2:$E$300,C$4) | D6: =COUNTIFS(Scope!$D$2:$D$300,$A6,Scope!$E$2:$E$300,D$4) | E6: =COUNTIFS(Scope!$D$2:$D$300,$A6,Scope!$E$2:$E$300,E$4) | F6: =SUM(B6:E6) | G6: =IF(F6=0,0,B6/F6)
A7: Could | B7: =COUNTIFS(Scope!$D$2:$D$300,$A7,Scope!$E$2:$E$300,B$4) | C7: =COUNTIFS(Scope!$D$2:$D$300,$A7,Scope!$E$2:$E$300,C$4) | D7: =COUNTIFS(Scope!$D$2:$D$300,$A7,Scope!$E$2:$E$300,D$4) | E7: =COUNTIFS(Scope!$D$2:$D$300,$A7,Scope!$E$2:$E$300,E$4) | F7: =SUM(B7:E7) | G7: =IF(F7=0,0,B7/F7)
A8: Won't | B8: =COUNTIFS(Scope!$D$2:$D$300,$A8,Scope!$E$2:$E$300,B$4) | C8: =COUNTIFS(Scope!$D$2:$D$300,$A8,Scope!$E$2:$E$300,C$4) | D8: =COUNTIFS(Scope!$D$2:$D$300,$A8,Scope!$E$2:$E$300,D$4) | E8: =COUNTIFS(Scope!$D$2:$D$300,$A8,Scope!$E$2:$E$300,E$4) | F8: =SUM(B8:E8) | G8: =IF(F8=0,0,B8/F8)
A9: Total | B9: =SUM(B5:B8) | C9: =SUM(C5:C8) | D9: =SUM(D5:D8) | E9: =SUM(E5:E8) | F9: =SUM(F5:F8) | G9: =IF(F9=0,0,B9/F9)
A11: Open Musts (not done) | B11: =COUNTIFS(Scope!$D$2:$D$300,"Must",Scope!$E$2:$E$300,"<>Done")
A12: Proposals awaiting the owner | B12: =COUNTIF(Scope!$H$2:$H$300,"Claude (proposed)")
